[2025-02-10 11:27:44,430][flwr][INFO] - Starting Flower ServerApp, config: num_rounds=20, no round_timeout
[2025-02-10 11:27:44,431][flwr][INFO] - 
[2025-02-10 11:27:44,431][flwr][INFO] - [INIT]
[2025-02-10 11:27:44,432][flwr][INFO] - Using initial global parameters provided by strategy
[2025-02-10 11:27:44,432][flwr][INFO] - Starting evaluation of initial global parameters
[2025-02-10 11:27:53,009][flwr][INFO] - initial parameters (loss, other metrics): 0.07212343354225159, {'accuracy': 0.0957}
[2025-02-10 11:27:53,009][flwr][INFO] - 
[2025-02-10 11:27:53,009][flwr][INFO] - [ROUND 1]
[2025-02-10 11:27:53,010][flwr][INFO] - configure_fit: strategy sampled 50 clients (out of 50)
[2025-02-10 11:29:06,388][flwr][ERROR] - An exception was raised when processing a message by RayBackend
[2025-02-10 11:29:06,388][flwr][ERROR] - [36mray::ClientAppActor.run()[39m (pid=2982, ip=172.27.85.201, actor_id=d3f5cc4b9cae25a70b3b930601000000, repr=<flwr.simulation.ray_transport.ray_actor.ClientAppActor object at 0x7f96ec62af90>)
  File "/home/theo_ubuntu/miniconda3/envs/flwr_25_DP/lib/python3.11/site-packages/requests/models.py", line 1024, in raise_for_status
    raise HTTPError(http_error_msg, response=self)
requests.exceptions.HTTPError: 504 Server Error: Gateway Time-out for url: https://huggingface.co/api/datasets/ylecun/mnist/paths-info/77f3279092a1c1579b2250db8eafed0ad422088c

The above exception was the direct cause of the following exception:

[36mray::ClientAppActor.run()[39m (pid=2982, ip=172.27.85.201, actor_id=d3f5cc4b9cae25a70b3b930601000000, repr=<flwr.simulation.ray_transport.ray_actor.ClientAppActor object at 0x7f96ec62af90>)
  File "/home/theo_ubuntu/miniconda3/envs/flwr_25_DP/lib/python3.11/site-packages/flwr/simulation/ray_transport/ray_actor.py", line 58, in run
    out_message = app(message=message, context=context)
                  ^^^^^^^^^^^^^^^^^^^^^^^^^^^^^^^^^^^^^
  File "/home/theo_ubuntu/miniconda3/envs/flwr_25_DP/lib/python3.11/site-packages/flwr/client/client_app.py", line 143, in __call__
    return self._call(message, context)
           ^^^^^^^^^^^^^^^^^^^^^^^^^^^^
  File "/home/theo_ubuntu/miniconda3/envs/flwr_25_DP/lib/python3.11/site-packages/flwr/client/client_app.py", line 126, in ffn
    out_message = handle_legacy_message_from_msgtype(
                  ^^^^^^^^^^^^^^^^^^^^^^^^^^^^^^^^^^^
  File "/home/theo_ubuntu/miniconda3/envs/flwr_25_DP/lib/python3.11/site-packages/flwr/client/message_handler/message_handler.py", line 96, in handle_legacy_message_from_msgtype
    client = client_fn(context)
             ^^^^^^^^^^^^^^^^^^
  File "/home/theo_ubuntu/Diplomatic_incident/Differential_Privacy/Mnist_2/opacus_fl/client_utils.py", line 105, in client_fn
    trainloader, valloader, _= load_datasets(cfg, partition_id)
                               ^^^^^^^^^^^^^^^^^^^^^^^^^^^^^^^^
  File "/home/theo_ubuntu/Diplomatic_incident/Differential_Privacy/Mnist_2/opacus_fl/data_utils.py", line 27, in load_datasets
    partition = fds.load_partition(partition_id)
                ^^^^^^^^^^^^^^^^^^^^^^^^^^^^^^^^
  File "/home/theo_ubuntu/miniconda3/envs/flwr_25_DP/lib/python3.11/site-packages/flwr_datasets/federated_dataset.py", line 177, in load_partition
    self._prepare_dataset()
  File "/home/theo_ubuntu/miniconda3/envs/flwr_25_DP/lib/python3.11/site-packages/flwr_datasets/federated_dataset.py", line 314, in _prepare_dataset
    self._dataset = datasets.load_dataset(
                    ^^^^^^^^^^^^^^^^^^^^^^
  File "/home/theo_ubuntu/miniconda3/envs/flwr_25_DP/lib/python3.11/site-packages/datasets/load.py", line 2132, in load_dataset
    builder_instance = load_dataset_builder(
                       ^^^^^^^^^^^^^^^^^^^^^
  File "/home/theo_ubuntu/miniconda3/envs/flwr_25_DP/lib/python3.11/site-packages/datasets/load.py", line 1890, in load_dataset_builder
    builder_instance: DatasetBuilder = builder_cls(
                                       ^^^^^^^^^^^^
  File "/home/theo_ubuntu/miniconda3/envs/flwr_25_DP/lib/python3.11/site-packages/datasets/builder.py", line 342, in __init__
    self.config, self.config_id = self._create_builder_config(
                                  ^^^^^^^^^^^^^^^^^^^^^^^^^^^^
  File "/home/theo_ubuntu/miniconda3/envs/flwr_25_DP/lib/python3.11/site-packages/datasets/builder.py", line 597, in _create_builder_config
    builder_config._resolve_data_files(
  File "/home/theo_ubuntu/miniconda3/envs/flwr_25_DP/lib/python3.11/site-packages/datasets/builder.py", line 206, in _resolve_data_files
    self.data_files = self.data_files.resolve(base_path, download_config)
                      ^^^^^^^^^^^^^^^^^^^^^^^^^^^^^^^^^^^^^^^^^^^^^^^^^^^
  File "/home/theo_ubuntu/miniconda3/envs/flwr_25_DP/lib/python3.11/site-packages/datasets/data_files.py", line 818, in resolve
    out[key] = data_files_patterns_list.resolve(base_path, download_config)
               ^^^^^^^^^^^^^^^^^^^^^^^^^^^^^^^^^^^^^^^^^^^^^^^^^^^^^^^^^^^^
  File "/home/theo_ubuntu/miniconda3/envs/flwr_25_DP/lib/python3.11/site-packages/datasets/data_files.py", line 771, in resolve
    resolve_pattern(
  File "/home/theo_ubuntu/miniconda3/envs/flwr_25_DP/lib/python3.11/site-packages/datasets/data_files.py", line 388, in resolve_pattern
    for filepath, info in fs.glob(pattern, detail=True, **glob_kwargs).items()
                          ^^^^^^^^^^^^^^^^^^^^^^^^^^^^^^^^^^^^^^^^^^^^
  File "/home/theo_ubuntu/miniconda3/envs/flwr_25_DP/lib/python3.11/site-packages/huggingface_hub/hf_file_system.py", line 521, in glob
    return super().glob(path, **kwargs)
           ^^^^^^^^^^^^^^^^^^^^^^^^^^^^
  File "/home/theo_ubuntu/miniconda3/envs/flwr_25_DP/lib/python3.11/site-packages/fsspec/spec.py", line 611, in glob
    allpaths = self.find(root, maxdepth=depth, withdirs=True, detail=True, **kwargs)
               ^^^^^^^^^^^^^^^^^^^^^^^^^^^^^^^^^^^^^^^^^^^^^^^^^^^^^^^^^^^^^^^^^^^^^
  File "/home/theo_ubuntu/miniconda3/envs/flwr_25_DP/lib/python3.11/site-packages/huggingface_hub/hf_file_system.py", line 556, in find
    return super().find(
           ^^^^^^^^^^^^^
  File "/home/theo_ubuntu/miniconda3/envs/flwr_25_DP/lib/python3.11/site-packages/fsspec/spec.py", line 502, in find
    out[path] = self.info(path)
                ^^^^^^^^^^^^^^^
  File "/home/theo_ubuntu/miniconda3/envs/flwr_25_DP/lib/python3.11/site-packages/huggingface_hub/hf_file_system.py", line 719, in info
    paths_info = self._api.get_paths_info(
                 ^^^^^^^^^^^^^^^^^^^^^^^^^
  File "/home/theo_ubuntu/miniconda3/envs/flwr_25_DP/lib/python3.11/site-packages/huggingface_hub/utils/_validators.py", line 114, in _inner_fn
    return fn(*args, **kwargs)
           ^^^^^^^^^^^^^^^^^^^
  File "/home/theo_ubuntu/miniconda3/envs/flwr_25_DP/lib/python3.11/site-packages/huggingface_hub/hf_api.py", line 3303, in get_paths_info
    hf_raise_for_status(response)
  File "/home/theo_ubuntu/miniconda3/envs/flwr_25_DP/lib/python3.11/site-packages/huggingface_hub/utils/_http.py", line 477, in hf_raise_for_status
    raise _format(HfHubHTTPError, str(e), response) from e
huggingface_hub.errors.HfHubHTTPError: 504 Server Error: Gateway Time-out for url: https://huggingface.co/api/datasets/ylecun/mnist/paths-info/77f3279092a1c1579b2250db8eafed0ad422088c

The above exception was the direct cause of the following exception:

[36mray::ClientAppActor.run()[39m (pid=2982, ip=172.27.85.201, actor_id=d3f5cc4b9cae25a70b3b930601000000, repr=<flwr.simulation.ray_transport.ray_actor.ClientAppActor object at 0x7f96ec62af90>)
           ^^^^^^^^^^^^^^^^^^^^^^^^^^^^^^^^^^^^
           ^^^^^^^^^^^^^^^^^^^^^^^^^^^^^^^
  File "/home/theo_ubuntu/miniconda3/envs/flwr_25_DP/lib/python3.11/site-packages/flwr/simulation/ray_transport/ray_actor.py", line 64, in run
    raise ClientAppException(str(ex)) from ex
flwr.client.client_app.ClientAppException: 
Exception ClientAppException occurred. Message: 504 Server Error: Gateway Time-out for url: https://huggingface.co/api/datasets/ylecun/mnist/paths-info/77f3279092a1c1579b2250db8eafed0ad422088c
[2025-02-10 11:29:06,390][flwr][ERROR] - Traceback (most recent call last):
  File "/home/theo_ubuntu/miniconda3/envs/flwr_25_DP/lib/python3.11/site-packages/flwr/server/superlink/fleet/vce/vce_api.py", line 112, in worker
    out_mssg, updated_context = backend.process_message(message, context)
                                ^^^^^^^^^^^^^^^^^^^^^^^^^^^^^^^^^^^^^^^^^
  File "/home/theo_ubuntu/miniconda3/envs/flwr_25_DP/lib/python3.11/site-packages/flwr/server/superlink/fleet/vce/backend/raybackend.py", line 187, in process_message
    raise ex
  File "/home/theo_ubuntu/miniconda3/envs/flwr_25_DP/lib/python3.11/site-packages/flwr/server/superlink/fleet/vce/backend/raybackend.py", line 175, in process_message
    ) = self.pool.fetch_result_and_return_actor_to_pool(future)
        ^^^^^^^^^^^^^^^^^^^^^^^^^^^^^^^^^^^^^^^^^^^^^^^^^^^^^^^
  File "/home/theo_ubuntu/miniconda3/envs/flwr_25_DP/lib/python3.11/site-packages/flwr/simulation/ray_transport/ray_actor.py", line 478, in fetch_result_and_return_actor_to_pool
    _, out_mssg, updated_context = ray.get(future)
                                   ^^^^^^^^^^^^^^^
  File "/home/theo_ubuntu/miniconda3/envs/flwr_25_DP/lib/python3.11/site-packages/ray/_private/auto_init_hook.py", line 21, in auto_init_wrapper
    return fn(*args, **kwargs)
           ^^^^^^^^^^^^^^^^^^^
  File "/home/theo_ubuntu/miniconda3/envs/flwr_25_DP/lib/python3.11/site-packages/ray/_private/client_mode_hook.py", line 103, in wrapper
    return func(*args, **kwargs)
           ^^^^^^^^^^^^^^^^^^^^^
  File "/home/theo_ubuntu/miniconda3/envs/flwr_25_DP/lib/python3.11/site-packages/ray/_private/worker.py", line 2667, in get
    values, debugger_breakpoint = worker.get_objects(object_refs, timeout=timeout)
                                  ^^^^^^^^^^^^^^^^^^^^^^^^^^^^^^^^^^^^^^^^^^^^^^^^
  File "/home/theo_ubuntu/miniconda3/envs/flwr_25_DP/lib/python3.11/site-packages/ray/_private/worker.py", line 864, in get_objects
    raise value.as_instanceof_cause()
ray.exceptions.RayTaskError(ClientAppException): [36mray::ClientAppActor.run()[39m (pid=2982, ip=172.27.85.201, actor_id=d3f5cc4b9cae25a70b3b930601000000, repr=<flwr.simulation.ray_transport.ray_actor.ClientAppActor object at 0x7f96ec62af90>)
  File "/home/theo_ubuntu/miniconda3/envs/flwr_25_DP/lib/python3.11/site-packages/requests/models.py", line 1024, in raise_for_status
    raise HTTPError(http_error_msg, response=self)
requests.exceptions.HTTPError: 504 Server Error: Gateway Time-out for url: https://huggingface.co/api/datasets/ylecun/mnist/paths-info/77f3279092a1c1579b2250db8eafed0ad422088c

The above exception was the direct cause of the following exception:

[36mray::ClientAppActor.run()[39m (pid=2982, ip=172.27.85.201, actor_id=d3f5cc4b9cae25a70b3b930601000000, repr=<flwr.simulation.ray_transport.ray_actor.ClientAppActor object at 0x7f96ec62af90>)
  File "/home/theo_ubuntu/miniconda3/envs/flwr_25_DP/lib/python3.11/site-packages/flwr/simulation/ray_transport/ray_actor.py", line 58, in run
    out_message = app(message=message, context=context)
                  ^^^^^^^^^^^^^^^^^^^^^^^^^^^^^^^^^^^^^
  File "/home/theo_ubuntu/miniconda3/envs/flwr_25_DP/lib/python3.11/site-packages/flwr/client/client_app.py", line 143, in __call__
    return self._call(message, context)
           ^^^^^^^^^^^^^^^^^^^^^^^^^^^^
  File "/home/theo_ubuntu/miniconda3/envs/flwr_25_DP/lib/python3.11/site-packages/flwr/client/client_app.py", line 126, in ffn
    out_message = handle_legacy_message_from_msgtype(
                  ^^^^^^^^^^^^^^^^^^^^^^^^^^^^^^^^^^^
  File "/home/theo_ubuntu/miniconda3/envs/flwr_25_DP/lib/python3.11/site-packages/flwr/client/message_handler/message_handler.py", line 96, in handle_legacy_message_from_msgtype
    client = client_fn(context)
             ^^^^^^^^^^^^^^^^^^
  File "/home/theo_ubuntu/Diplomatic_incident/Differential_Privacy/Mnist_2/opacus_fl/client_utils.py", line 105, in client_fn
    trainloader, valloader, _= load_datasets(cfg, partition_id)
                               ^^^^^^^^^^^^^^^^^^^^^^^^^^^^^^^^
  File "/home/theo_ubuntu/Diplomatic_incident/Differential_Privacy/Mnist_2/opacus_fl/data_utils.py", line 27, in load_datasets
    partition = fds.load_partition(partition_id)
                ^^^^^^^^^^^^^^^^^^^^^^^^^^^^^^^^
  File "/home/theo_ubuntu/miniconda3/envs/flwr_25_DP/lib/python3.11/site-packages/flwr_datasets/federated_dataset.py", line 177, in load_partition
    self._prepare_dataset()
  File "/home/theo_ubuntu/miniconda3/envs/flwr_25_DP/lib/python3.11/site-packages/flwr_datasets/federated_dataset.py", line 314, in _prepare_dataset
    self._dataset = datasets.load_dataset(
                    ^^^^^^^^^^^^^^^^^^^^^^
  File "/home/theo_ubuntu/miniconda3/envs/flwr_25_DP/lib/python3.11/site-packages/datasets/load.py", line 2132, in load_dataset
    builder_instance = load_dataset_builder(
                       ^^^^^^^^^^^^^^^^^^^^^
  File "/home/theo_ubuntu/miniconda3/envs/flwr_25_DP/lib/python3.11/site-packages/datasets/load.py", line 1890, in load_dataset_builder
    builder_instance: DatasetBuilder = builder_cls(
                                       ^^^^^^^^^^^^
  File "/home/theo_ubuntu/miniconda3/envs/flwr_25_DP/lib/python3.11/site-packages/datasets/builder.py", line 342, in __init__
    self.config, self.config_id = self._create_builder_config(
                                  ^^^^^^^^^^^^^^^^^^^^^^^^^^^^
  File "/home/theo_ubuntu/miniconda3/envs/flwr_25_DP/lib/python3.11/site-packages/datasets/builder.py", line 597, in _create_builder_config
    builder_config._resolve_data_files(
  File "/home/theo_ubuntu/miniconda3/envs/flwr_25_DP/lib/python3.11/site-packages/datasets/builder.py", line 206, in _resolve_data_files
    self.data_files = self.data_files.resolve(base_path, download_config)
                      ^^^^^^^^^^^^^^^^^^^^^^^^^^^^^^^^^^^^^^^^^^^^^^^^^^^
  File "/home/theo_ubuntu/miniconda3/envs/flwr_25_DP/lib/python3.11/site-packages/datasets/data_files.py", line 818, in resolve
    out[key] = data_files_patterns_list.resolve(base_path, download_config)
               ^^^^^^^^^^^^^^^^^^^^^^^^^^^^^^^^^^^^^^^^^^^^^^^^^^^^^^^^^^^^
  File "/home/theo_ubuntu/miniconda3/envs/flwr_25_DP/lib/python3.11/site-packages/datasets/data_files.py", line 771, in resolve
    resolve_pattern(
  File "/home/theo_ubuntu/miniconda3/envs/flwr_25_DP/lib/python3.11/site-packages/datasets/data_files.py", line 388, in resolve_pattern
    for filepath, info in fs.glob(pattern, detail=True, **glob_kwargs).items()
                          ^^^^^^^^^^^^^^^^^^^^^^^^^^^^^^^^^^^^^^^^^^^^
  File "/home/theo_ubuntu/miniconda3/envs/flwr_25_DP/lib/python3.11/site-packages/huggingface_hub/hf_file_system.py", line 521, in glob
    return super().glob(path, **kwargs)
           ^^^^^^^^^^^^^^^^^^^^^^^^^^^^
  File "/home/theo_ubuntu/miniconda3/envs/flwr_25_DP/lib/python3.11/site-packages/fsspec/spec.py", line 611, in glob
    allpaths = self.find(root, maxdepth=depth, withdirs=True, detail=True, **kwargs)
               ^^^^^^^^^^^^^^^^^^^^^^^^^^^^^^^^^^^^^^^^^^^^^^^^^^^^^^^^^^^^^^^^^^^^^
  File "/home/theo_ubuntu/miniconda3/envs/flwr_25_DP/lib/python3.11/site-packages/huggingface_hub/hf_file_system.py", line 556, in find
    return super().find(
           ^^^^^^^^^^^^^
  File "/home/theo_ubuntu/miniconda3/envs/flwr_25_DP/lib/python3.11/site-packages/fsspec/spec.py", line 502, in find
    out[path] = self.info(path)
                ^^^^^^^^^^^^^^^
  File "/home/theo_ubuntu/miniconda3/envs/flwr_25_DP/lib/python3.11/site-packages/huggingface_hub/hf_file_system.py", line 719, in info
    paths_info = self._api.get_paths_info(
                 ^^^^^^^^^^^^^^^^^^^^^^^^^
  File "/home/theo_ubuntu/miniconda3/envs/flwr_25_DP/lib/python3.11/site-packages/huggingface_hub/utils/_validators.py", line 114, in _inner_fn
    return fn(*args, **kwargs)
           ^^^^^^^^^^^^^^^^^^^
  File "/home/theo_ubuntu/miniconda3/envs/flwr_25_DP/lib/python3.11/site-packages/huggingface_hub/hf_api.py", line 3303, in get_paths_info
    hf_raise_for_status(response)
  File "/home/theo_ubuntu/miniconda3/envs/flwr_25_DP/lib/python3.11/site-packages/huggingface_hub/utils/_http.py", line 477, in hf_raise_for_status
    raise _format(HfHubHTTPError, str(e), response) from e
huggingface_hub.errors.HfHubHTTPError: 504 Server Error: Gateway Time-out for url: https://huggingface.co/api/datasets/ylecun/mnist/paths-info/77f3279092a1c1579b2250db8eafed0ad422088c

The above exception was the direct cause of the following exception:

[36mray::ClientAppActor.run()[39m (pid=2982, ip=172.27.85.201, actor_id=d3f5cc4b9cae25a70b3b930601000000, repr=<flwr.simulation.ray_transport.ray_actor.ClientAppActor object at 0x7f96ec62af90>)
           ^^^^^^^^^^^^^^^^^^^^^^^^^^^^^^^^^^^^
           ^^^^^^^^^^^^^^^^^^^^^^^^^^^^^^^
  File "/home/theo_ubuntu/miniconda3/envs/flwr_25_DP/lib/python3.11/site-packages/flwr/simulation/ray_transport/ray_actor.py", line 64, in run
    raise ClientAppException(str(ex)) from ex
flwr.client.client_app.ClientAppException: 
Exception ClientAppException occurred. Message: 504 Server Error: Gateway Time-out for url: https://huggingface.co/api/datasets/ylecun/mnist/paths-info/77f3279092a1c1579b2250db8eafed0ad422088c

[2025-02-10 11:30:32,132][flwr][INFO] - aggregate_fit: received 49 results and 1 failures
[2025-02-10 11:30:38,381][flwr][INFO] - fit progress: (1, 0.07180734941959381, {'accuracy': 0.153}, 165.3718007360003)
[2025-02-10 11:30:38,381][flwr][INFO] - configure_evaluate: strategy sampled 50 clients (out of 50)
[2025-02-10 11:31:27,194][flwr][ERROR] - An exception was raised when processing a message by RayBackend
[2025-02-10 11:31:27,195][flwr][ERROR] - [36mray::ClientAppActor.run()[39m (pid=2983, ip=172.27.85.201, actor_id=9f5e8677eb99ac5224520eb901000000, repr=<flwr.simulation.ray_transport.ray_actor.ClientAppActor object at 0x7fd7b40eeed0>)
  File "/home/theo_ubuntu/miniconda3/envs/flwr_25_DP/lib/python3.11/site-packages/requests/models.py", line 1024, in raise_for_status
    raise HTTPError(http_error_msg, response=self)
requests.exceptions.HTTPError: 504 Server Error: Gateway Time-out for url: https://huggingface.co/api/datasets/mnist/paths-info/77f3279092a1c1579b2250db8eafed0ad422088c

The above exception was the direct cause of the following exception:

[36mray::ClientAppActor.run()[39m (pid=2983, ip=172.27.85.201, actor_id=9f5e8677eb99ac5224520eb901000000, repr=<flwr.simulation.ray_transport.ray_actor.ClientAppActor object at 0x7fd7b40eeed0>)
  File "/home/theo_ubuntu/miniconda3/envs/flwr_25_DP/lib/python3.11/site-packages/flwr/simulation/ray_transport/ray_actor.py", line 58, in run
    out_message = app(message=message, context=context)
                  ^^^^^^^^^^^^^^^^^^^^^^^^^^^^^^^^^^^^^
  File "/home/theo_ubuntu/miniconda3/envs/flwr_25_DP/lib/python3.11/site-packages/flwr/client/client_app.py", line 143, in __call__
    return self._call(message, context)
           ^^^^^^^^^^^^^^^^^^^^^^^^^^^^
  File "/home/theo_ubuntu/miniconda3/envs/flwr_25_DP/lib/python3.11/site-packages/flwr/client/client_app.py", line 126, in ffn
    out_message = handle_legacy_message_from_msgtype(
                  ^^^^^^^^^^^^^^^^^^^^^^^^^^^^^^^^^^^
  File "/home/theo_ubuntu/miniconda3/envs/flwr_25_DP/lib/python3.11/site-packages/flwr/client/message_handler/message_handler.py", line 96, in handle_legacy_message_from_msgtype
    client = client_fn(context)
             ^^^^^^^^^^^^^^^^^^
  File "/home/theo_ubuntu/Diplomatic_incident/Differential_Privacy/Mnist_2/opacus_fl/client_utils.py", line 105, in client_fn
    trainloader, valloader, _= load_datasets(cfg, partition_id)
                               ^^^^^^^^^^^^^^^^^^^^^^^^^^^^^^^^
  File "/home/theo_ubuntu/Diplomatic_incident/Differential_Privacy/Mnist_2/opacus_fl/data_utils.py", line 27, in load_datasets
    partition = fds.load_partition(partition_id)
                ^^^^^^^^^^^^^^^^^^^^^^^^^^^^^^^^
  File "/home/theo_ubuntu/miniconda3/envs/flwr_25_DP/lib/python3.11/site-packages/flwr_datasets/federated_dataset.py", line 177, in load_partition
    self._prepare_dataset()
  File "/home/theo_ubuntu/miniconda3/envs/flwr_25_DP/lib/python3.11/site-packages/flwr_datasets/federated_dataset.py", line 314, in _prepare_dataset
    self._dataset = datasets.load_dataset(
                    ^^^^^^^^^^^^^^^^^^^^^^
  File "/home/theo_ubuntu/miniconda3/envs/flwr_25_DP/lib/python3.11/site-packages/datasets/load.py", line 2132, in load_dataset
    builder_instance = load_dataset_builder(
                       ^^^^^^^^^^^^^^^^^^^^^
  File "/home/theo_ubuntu/miniconda3/envs/flwr_25_DP/lib/python3.11/site-packages/datasets/load.py", line 1890, in load_dataset_builder
    builder_instance: DatasetBuilder = builder_cls(
                                       ^^^^^^^^^^^^
  File "/home/theo_ubuntu/miniconda3/envs/flwr_25_DP/lib/python3.11/site-packages/datasets/builder.py", line 342, in __init__
    self.config, self.config_id = self._create_builder_config(
                                  ^^^^^^^^^^^^^^^^^^^^^^^^^^^^
  File "/home/theo_ubuntu/miniconda3/envs/flwr_25_DP/lib/python3.11/site-packages/datasets/builder.py", line 597, in _create_builder_config
    builder_config._resolve_data_files(
  File "/home/theo_ubuntu/miniconda3/envs/flwr_25_DP/lib/python3.11/site-packages/datasets/builder.py", line 206, in _resolve_data_files
    self.data_files = self.data_files.resolve(base_path, download_config)
                      ^^^^^^^^^^^^^^^^^^^^^^^^^^^^^^^^^^^^^^^^^^^^^^^^^^^
  File "/home/theo_ubuntu/miniconda3/envs/flwr_25_DP/lib/python3.11/site-packages/datasets/data_files.py", line 818, in resolve
    out[key] = data_files_patterns_list.resolve(base_path, download_config)
               ^^^^^^^^^^^^^^^^^^^^^^^^^^^^^^^^^^^^^^^^^^^^^^^^^^^^^^^^^^^^
  File "/home/theo_ubuntu/miniconda3/envs/flwr_25_DP/lib/python3.11/site-packages/datasets/data_files.py", line 771, in resolve
    resolve_pattern(
  File "/home/theo_ubuntu/miniconda3/envs/flwr_25_DP/lib/python3.11/site-packages/datasets/data_files.py", line 388, in resolve_pattern
    for filepath, info in fs.glob(pattern, detail=True, **glob_kwargs).items()
                          ^^^^^^^^^^^^^^^^^^^^^^^^^^^^^^^^^^^^^^^^^^^^
  File "/home/theo_ubuntu/miniconda3/envs/flwr_25_DP/lib/python3.11/site-packages/huggingface_hub/hf_file_system.py", line 521, in glob
    return super().glob(path, **kwargs)
           ^^^^^^^^^^^^^^^^^^^^^^^^^^^^
  File "/home/theo_ubuntu/miniconda3/envs/flwr_25_DP/lib/python3.11/site-packages/fsspec/spec.py", line 611, in glob
    allpaths = self.find(root, maxdepth=depth, withdirs=True, detail=True, **kwargs)
               ^^^^^^^^^^^^^^^^^^^^^^^^^^^^^^^^^^^^^^^^^^^^^^^^^^^^^^^^^^^^^^^^^^^^^
  File "/home/theo_ubuntu/miniconda3/envs/flwr_25_DP/lib/python3.11/site-packages/huggingface_hub/hf_file_system.py", line 556, in find
    return super().find(
           ^^^^^^^^^^^^^
  File "/home/theo_ubuntu/miniconda3/envs/flwr_25_DP/lib/python3.11/site-packages/fsspec/spec.py", line 502, in find
    out[path] = self.info(path)
                ^^^^^^^^^^^^^^^
  File "/home/theo_ubuntu/miniconda3/envs/flwr_25_DP/lib/python3.11/site-packages/huggingface_hub/hf_file_system.py", line 719, in info
    paths_info = self._api.get_paths_info(
                 ^^^^^^^^^^^^^^^^^^^^^^^^^
  File "/home/theo_ubuntu/miniconda3/envs/flwr_25_DP/lib/python3.11/site-packages/huggingface_hub/utils/_validators.py", line 114, in _inner_fn
    return fn(*args, **kwargs)
           ^^^^^^^^^^^^^^^^^^^
  File "/home/theo_ubuntu/miniconda3/envs/flwr_25_DP/lib/python3.11/site-packages/huggingface_hub/hf_api.py", line 3303, in get_paths_info
    hf_raise_for_status(response)
  File "/home/theo_ubuntu/miniconda3/envs/flwr_25_DP/lib/python3.11/site-packages/huggingface_hub/utils/_http.py", line 477, in hf_raise_for_status
    raise _format(HfHubHTTPError, str(e), response) from e
huggingface_hub.errors.HfHubHTTPError: 504 Server Error: Gateway Time-out for url: https://huggingface.co/api/datasets/mnist/paths-info/77f3279092a1c1579b2250db8eafed0ad422088c

The above exception was the direct cause of the following exception:

[36mray::ClientAppActor.run()[39m (pid=2983, ip=172.27.85.201, actor_id=9f5e8677eb99ac5224520eb901000000, repr=<flwr.simulation.ray_transport.ray_actor.ClientAppActor object at 0x7fd7b40eeed0>)
           ^^^^^^^^^^^^^^^^^^^^^^^^^^^^^^^^^^^^
           ^^^^^^^^^^^^^^^^^^^^^^^^^^^^^^^
  File "/home/theo_ubuntu/miniconda3/envs/flwr_25_DP/lib/python3.11/site-packages/flwr/simulation/ray_transport/ray_actor.py", line 64, in run
    raise ClientAppException(str(ex)) from ex
flwr.client.client_app.ClientAppException: 
Exception ClientAppException occurred. Message: 504 Server Error: Gateway Time-out for url: https://huggingface.co/api/datasets/mnist/paths-info/77f3279092a1c1579b2250db8eafed0ad422088c
[2025-02-10 11:31:27,196][flwr][ERROR] - Traceback (most recent call last):
  File "/home/theo_ubuntu/miniconda3/envs/flwr_25_DP/lib/python3.11/site-packages/flwr/server/superlink/fleet/vce/vce_api.py", line 112, in worker
    out_mssg, updated_context = backend.process_message(message, context)
                                ^^^^^^^^^^^^^^^^^^^^^^^^^^^^^^^^^^^^^^^^^
  File "/home/theo_ubuntu/miniconda3/envs/flwr_25_DP/lib/python3.11/site-packages/flwr/server/superlink/fleet/vce/backend/raybackend.py", line 187, in process_message
    raise ex
  File "/home/theo_ubuntu/miniconda3/envs/flwr_25_DP/lib/python3.11/site-packages/flwr/server/superlink/fleet/vce/backend/raybackend.py", line 175, in process_message
    ) = self.pool.fetch_result_and_return_actor_to_pool(future)
        ^^^^^^^^^^^^^^^^^^^^^^^^^^^^^^^^^^^^^^^^^^^^^^^^^^^^^^^
  File "/home/theo_ubuntu/miniconda3/envs/flwr_25_DP/lib/python3.11/site-packages/flwr/simulation/ray_transport/ray_actor.py", line 478, in fetch_result_and_return_actor_to_pool
    _, out_mssg, updated_context = ray.get(future)
                                   ^^^^^^^^^^^^^^^
  File "/home/theo_ubuntu/miniconda3/envs/flwr_25_DP/lib/python3.11/site-packages/ray/_private/auto_init_hook.py", line 21, in auto_init_wrapper
    return fn(*args, **kwargs)
           ^^^^^^^^^^^^^^^^^^^
  File "/home/theo_ubuntu/miniconda3/envs/flwr_25_DP/lib/python3.11/site-packages/ray/_private/client_mode_hook.py", line 103, in wrapper
    return func(*args, **kwargs)
           ^^^^^^^^^^^^^^^^^^^^^
  File "/home/theo_ubuntu/miniconda3/envs/flwr_25_DP/lib/python3.11/site-packages/ray/_private/worker.py", line 2667, in get
    values, debugger_breakpoint = worker.get_objects(object_refs, timeout=timeout)
                                  ^^^^^^^^^^^^^^^^^^^^^^^^^^^^^^^^^^^^^^^^^^^^^^^^
  File "/home/theo_ubuntu/miniconda3/envs/flwr_25_DP/lib/python3.11/site-packages/ray/_private/worker.py", line 864, in get_objects
    raise value.as_instanceof_cause()
ray.exceptions.RayTaskError(ClientAppException): [36mray::ClientAppActor.run()[39m (pid=2983, ip=172.27.85.201, actor_id=9f5e8677eb99ac5224520eb901000000, repr=<flwr.simulation.ray_transport.ray_actor.ClientAppActor object at 0x7fd7b40eeed0>)
  File "/home/theo_ubuntu/miniconda3/envs/flwr_25_DP/lib/python3.11/site-packages/requests/models.py", line 1024, in raise_for_status
    raise HTTPError(http_error_msg, response=self)
requests.exceptions.HTTPError: 504 Server Error: Gateway Time-out for url: https://huggingface.co/api/datasets/mnist/paths-info/77f3279092a1c1579b2250db8eafed0ad422088c

The above exception was the direct cause of the following exception:

[36mray::ClientAppActor.run()[39m (pid=2983, ip=172.27.85.201, actor_id=9f5e8677eb99ac5224520eb901000000, repr=<flwr.simulation.ray_transport.ray_actor.ClientAppActor object at 0x7fd7b40eeed0>)
  File "/home/theo_ubuntu/miniconda3/envs/flwr_25_DP/lib/python3.11/site-packages/flwr/simulation/ray_transport/ray_actor.py", line 58, in run
    out_message = app(message=message, context=context)
                  ^^^^^^^^^^^^^^^^^^^^^^^^^^^^^^^^^^^^^
  File "/home/theo_ubuntu/miniconda3/envs/flwr_25_DP/lib/python3.11/site-packages/flwr/client/client_app.py", line 143, in __call__
    return self._call(message, context)
           ^^^^^^^^^^^^^^^^^^^^^^^^^^^^
  File "/home/theo_ubuntu/miniconda3/envs/flwr_25_DP/lib/python3.11/site-packages/flwr/client/client_app.py", line 126, in ffn
    out_message = handle_legacy_message_from_msgtype(
                  ^^^^^^^^^^^^^^^^^^^^^^^^^^^^^^^^^^^
  File "/home/theo_ubuntu/miniconda3/envs/flwr_25_DP/lib/python3.11/site-packages/flwr/client/message_handler/message_handler.py", line 96, in handle_legacy_message_from_msgtype
    client = client_fn(context)
             ^^^^^^^^^^^^^^^^^^
  File "/home/theo_ubuntu/Diplomatic_incident/Differential_Privacy/Mnist_2/opacus_fl/client_utils.py", line 105, in client_fn
    trainloader, valloader, _= load_datasets(cfg, partition_id)
                               ^^^^^^^^^^^^^^^^^^^^^^^^^^^^^^^^
  File "/home/theo_ubuntu/Diplomatic_incident/Differential_Privacy/Mnist_2/opacus_fl/data_utils.py", line 27, in load_datasets
    partition = fds.load_partition(partition_id)
                ^^^^^^^^^^^^^^^^^^^^^^^^^^^^^^^^
  File "/home/theo_ubuntu/miniconda3/envs/flwr_25_DP/lib/python3.11/site-packages/flwr_datasets/federated_dataset.py", line 177, in load_partition
    self._prepare_dataset()
  File "/home/theo_ubuntu/miniconda3/envs/flwr_25_DP/lib/python3.11/site-packages/flwr_datasets/federated_dataset.py", line 314, in _prepare_dataset
    self._dataset = datasets.load_dataset(
                    ^^^^^^^^^^^^^^^^^^^^^^
  File "/home/theo_ubuntu/miniconda3/envs/flwr_25_DP/lib/python3.11/site-packages/datasets/load.py", line 2132, in load_dataset
    builder_instance = load_dataset_builder(
                       ^^^^^^^^^^^^^^^^^^^^^
  File "/home/theo_ubuntu/miniconda3/envs/flwr_25_DP/lib/python3.11/site-packages/datasets/load.py", line 1890, in load_dataset_builder
    builder_instance: DatasetBuilder = builder_cls(
                                       ^^^^^^^^^^^^
  File "/home/theo_ubuntu/miniconda3/envs/flwr_25_DP/lib/python3.11/site-packages/datasets/builder.py", line 342, in __init__
    self.config, self.config_id = self._create_builder_config(
                                  ^^^^^^^^^^^^^^^^^^^^^^^^^^^^
  File "/home/theo_ubuntu/miniconda3/envs/flwr_25_DP/lib/python3.11/site-packages/datasets/builder.py", line 597, in _create_builder_config
    builder_config._resolve_data_files(
  File "/home/theo_ubuntu/miniconda3/envs/flwr_25_DP/lib/python3.11/site-packages/datasets/builder.py", line 206, in _resolve_data_files
    self.data_files = self.data_files.resolve(base_path, download_config)
                      ^^^^^^^^^^^^^^^^^^^^^^^^^^^^^^^^^^^^^^^^^^^^^^^^^^^
  File "/home/theo_ubuntu/miniconda3/envs/flwr_25_DP/lib/python3.11/site-packages/datasets/data_files.py", line 818, in resolve
    out[key] = data_files_patterns_list.resolve(base_path, download_config)
               ^^^^^^^^^^^^^^^^^^^^^^^^^^^^^^^^^^^^^^^^^^^^^^^^^^^^^^^^^^^^
  File "/home/theo_ubuntu/miniconda3/envs/flwr_25_DP/lib/python3.11/site-packages/datasets/data_files.py", line 771, in resolve
    resolve_pattern(
  File "/home/theo_ubuntu/miniconda3/envs/flwr_25_DP/lib/python3.11/site-packages/datasets/data_files.py", line 388, in resolve_pattern
    for filepath, info in fs.glob(pattern, detail=True, **glob_kwargs).items()
                          ^^^^^^^^^^^^^^^^^^^^^^^^^^^^^^^^^^^^^^^^^^^^
  File "/home/theo_ubuntu/miniconda3/envs/flwr_25_DP/lib/python3.11/site-packages/huggingface_hub/hf_file_system.py", line 521, in glob
    return super().glob(path, **kwargs)
           ^^^^^^^^^^^^^^^^^^^^^^^^^^^^
  File "/home/theo_ubuntu/miniconda3/envs/flwr_25_DP/lib/python3.11/site-packages/fsspec/spec.py", line 611, in glob
    allpaths = self.find(root, maxdepth=depth, withdirs=True, detail=True, **kwargs)
               ^^^^^^^^^^^^^^^^^^^^^^^^^^^^^^^^^^^^^^^^^^^^^^^^^^^^^^^^^^^^^^^^^^^^^
  File "/home/theo_ubuntu/miniconda3/envs/flwr_25_DP/lib/python3.11/site-packages/huggingface_hub/hf_file_system.py", line 556, in find
    return super().find(
           ^^^^^^^^^^^^^
  File "/home/theo_ubuntu/miniconda3/envs/flwr_25_DP/lib/python3.11/site-packages/fsspec/spec.py", line 502, in find
    out[path] = self.info(path)
                ^^^^^^^^^^^^^^^
  File "/home/theo_ubuntu/miniconda3/envs/flwr_25_DP/lib/python3.11/site-packages/huggingface_hub/hf_file_system.py", line 719, in info
    paths_info = self._api.get_paths_info(
                 ^^^^^^^^^^^^^^^^^^^^^^^^^
  File "/home/theo_ubuntu/miniconda3/envs/flwr_25_DP/lib/python3.11/site-packages/huggingface_hub/utils/_validators.py", line 114, in _inner_fn
    return fn(*args, **kwargs)
           ^^^^^^^^^^^^^^^^^^^
  File "/home/theo_ubuntu/miniconda3/envs/flwr_25_DP/lib/python3.11/site-packages/huggingface_hub/hf_api.py", line 3303, in get_paths_info
    hf_raise_for_status(response)
  File "/home/theo_ubuntu/miniconda3/envs/flwr_25_DP/lib/python3.11/site-packages/huggingface_hub/utils/_http.py", line 477, in hf_raise_for_status
    raise _format(HfHubHTTPError, str(e), response) from e
huggingface_hub.errors.HfHubHTTPError: 504 Server Error: Gateway Time-out for url: https://huggingface.co/api/datasets/mnist/paths-info/77f3279092a1c1579b2250db8eafed0ad422088c

The above exception was the direct cause of the following exception:

[36mray::ClientAppActor.run()[39m (pid=2983, ip=172.27.85.201, actor_id=9f5e8677eb99ac5224520eb901000000, repr=<flwr.simulation.ray_transport.ray_actor.ClientAppActor object at 0x7fd7b40eeed0>)
           ^^^^^^^^^^^^^^^^^^^^^^^^^^^^^^^^^^^^
           ^^^^^^^^^^^^^^^^^^^^^^^^^^^^^^^
  File "/home/theo_ubuntu/miniconda3/envs/flwr_25_DP/lib/python3.11/site-packages/flwr/simulation/ray_transport/ray_actor.py", line 64, in run
    raise ClientAppException(str(ex)) from ex
flwr.client.client_app.ClientAppException: 
Exception ClientAppException occurred. Message: 504 Server Error: Gateway Time-out for url: https://huggingface.co/api/datasets/mnist/paths-info/77f3279092a1c1579b2250db8eafed0ad422088c

[2025-02-10 11:32:16,768][flwr][INFO] - aggregate_evaluate: received 49 results and 1 failures
[2025-02-10 11:32:16,768][flwr][INFO] - 
[2025-02-10 11:32:16,768][flwr][INFO] - [ROUND 2]
[2025-02-10 11:32:16,768][flwr][INFO] - configure_fit: strategy sampled 50 clients (out of 50)
[2025-02-10 11:33:19,927][flwr][INFO] - aggregate_fit: received 50 results and 0 failures
[2025-02-10 11:33:25,416][flwr][INFO] - fit progress: (2, 0.07140804662704468, {'accuracy': 0.2075}, 332.40656897101144)
[2025-02-10 11:33:25,416][flwr][INFO] - configure_evaluate: strategy sampled 50 clients (out of 50)
[2025-02-10 11:34:20,323][flwr][INFO] - aggregate_evaluate: received 50 results and 0 failures
[2025-02-10 11:34:20,324][flwr][INFO] - 
[2025-02-10 11:34:20,324][flwr][INFO] - [ROUND 3]
[2025-02-10 11:34:20,324][flwr][INFO] - configure_fit: strategy sampled 50 clients (out of 50)
[2025-02-10 11:35:22,783][flwr][INFO] - aggregate_fit: received 50 results and 0 failures
[2025-02-10 11:35:28,994][flwr][INFO] - fit progress: (3, 0.07079141073226929, {'accuracy': 0.2396}, 455.984679494999)
[2025-02-10 11:35:28,994][flwr][INFO] - configure_evaluate: strategy sampled 50 clients (out of 50)
[2025-02-10 11:36:26,211][flwr][INFO] - aggregate_evaluate: received 50 results and 0 failures
[2025-02-10 11:36:26,212][flwr][INFO] - 
[2025-02-10 11:36:26,212][flwr][INFO] - [ROUND 4]
[2025-02-10 11:36:26,212][flwr][INFO] - configure_fit: strategy sampled 50 clients (out of 50)
[2025-02-10 11:37:28,880][flwr][INFO] - aggregate_fit: received 50 results and 0 failures
[2025-02-10 11:37:34,480][flwr][INFO] - fit progress: (4, 0.06980083518028259, {'accuracy': 0.2984}, 581.4701828100078)
[2025-02-10 11:37:34,480][flwr][INFO] - configure_evaluate: strategy sampled 50 clients (out of 50)
[2025-02-10 11:38:30,992][flwr][INFO] - aggregate_evaluate: received 50 results and 0 failures
[2025-02-10 11:38:30,993][flwr][INFO] - 
[2025-02-10 11:38:30,993][flwr][INFO] - [ROUND 5]
[2025-02-10 11:38:30,993][flwr][INFO] - configure_fit: strategy sampled 50 clients (out of 50)
[2025-02-10 11:39:34,344][flwr][INFO] - aggregate_fit: received 50 results and 0 failures
[2025-02-10 11:39:40,190][flwr][INFO] - fit progress: (5, 0.06810401005744934, {'accuracy': 0.3816}, 707.1802745090099)
[2025-02-10 11:39:40,190][flwr][INFO] - configure_evaluate: strategy sampled 50 clients (out of 50)
[2025-02-10 11:40:35,177][flwr][INFO] - aggregate_evaluate: received 50 results and 0 failures
[2025-02-10 11:40:35,177][flwr][INFO] - 
[2025-02-10 11:40:35,177][flwr][INFO] - [ROUND 6]
[2025-02-10 11:40:35,177][flwr][INFO] - configure_fit: strategy sampled 50 clients (out of 50)
[2025-02-10 11:41:35,223][flwr][INFO] - aggregate_fit: received 50 results and 0 failures
[2025-02-10 11:41:40,823][flwr][INFO] - fit progress: (6, 0.06548283524513245, {'accuracy': 0.4379}, 827.8139489450114)
[2025-02-10 11:41:40,824][flwr][INFO] - configure_evaluate: strategy sampled 50 clients (out of 50)
[2025-02-10 11:42:35,407][flwr][INFO] - aggregate_evaluate: received 50 results and 0 failures
[2025-02-10 11:42:35,408][flwr][INFO] - 
[2025-02-10 11:42:35,408][flwr][INFO] - [ROUND 7]
[2025-02-10 11:42:35,408][flwr][INFO] - configure_fit: strategy sampled 50 clients (out of 50)
